# None响应修复报告

## 问题分析

根据测试文件 `counter_test_utf8_fixed_20250807_110928.txt` 的分析，发现了以下关键问题：

### 1. 核心错误：智能体执行失败
```
❌ 智能体 enhanced_real_verilog_agent 执行任务失败: object of type 'NoneType' has no len()
❌ 智能体 enhanced_real_code_review_agent 执行任务失败: object of type 'NoneType' has no len()
```

### 2. 智能体被禁用
```
⚠️ 智能体 enhanced_real_verilog_agent 连续失败次数过多，已暂时禁用
⚠️ 智能体 enhanced_real_code_review_agent 连续失败次数过多，已暂时禁用
```

### 3. 工具调用参数问题
```
⚠️ 工具执行失败 analyze_agent_result (尝试 1): LLMCoordinatorAgent._tool_analyze_agent_result() got an unexpected keyword argument 'task_id'
```

## 根本原因

问题出现在 `BaseAgent` 的 `process_with_function_calling` 方法中，当LLM返回 `None` 响应时，代码尝试调用 `len(response)` 导致错误。

## 修复方案

### 1. 修复 `BaseAgent` 中的 `None` 响应处理

**文件**: `core/base_agent.py`

**修复内容**:
- 在 `_execute_single_task_cycle` 方法中添加 `None` 响应检查
- 确保LLM响应不为 `None` 后再调用 `len()` 函数
- 提供默认响应避免程序崩溃

```python
# 调用LLM
llm_response = await self._call_llm_for_function_calling(conversation)

# 🔧 修复：检查LLM响应是否为None
if llm_response is None:
    self.logger.error(f"❌ LLM返回了None响应")
    llm_response = "LLM调用失败，未返回有效响应"

# 计算持续时间
duration = time.time() - llm_start_time
conversation_id = getattr(self, 'current_conversation_id', f"{self.agent_id}_{int(time.time())}")

self.logger.info(f"🔍 [{self.role.upper()}] LLM响应长度: {len(llm_response)}")
```

### 2. 修复响应长度检查

**修复内容**:
- 在检查响应长度前确保响应不为 `None`

```python
# 如果响应太短（可能只是确认消息），尝试生成更详细的总结
if llm_response and len(llm_response.strip()) < 100:
```

### 3. 统一智能体LLM调用方式

**文件**: `agents/enhanced_real_code_reviewer.py`

**修复内容**:
- 将代码审查智能体的LLM调用方式改为使用统一的LLM管理器
- 确保所有智能体使用相同的错误处理机制

```python
async def _call_llm_for_function_calling(self, conversation: List[Dict[str, str]]) -> str:
    """使用统一的LLM通信管理器进行Function Calling调用"""
    return await self.llm_manager.call_llm_for_function_calling(conversation)
```

### 4. 增强LLM管理器的错误处理

**文件**: `core/llm_communication/managers/client_manager.py`

**修复内容**:
- 在 `call_llm_for_function_calling` 方法中添加 `None` 响应检查
- 提供默认响应避免返回 `None`

```python
# 🔧 修复：确保响应不为None
if response is None:
    self.logger.warning("⚠️ LLM响应为空，返回默认响应")
    response = "我理解了您的请求，但当前无法生成有效响应。请稍后重试。"
```

## 修复效果

### ✅ 解决的问题

1. **消除了 `NoneType` 错误**
   - 所有LLM调用现在都有适当的 `None` 检查
   - 提供了默认响应避免程序崩溃

2. **统一了智能体LLM调用方式**
   - 所有智能体现在使用统一的LLM管理器
   - 确保了一致的错误处理机制

3. **改进了错误恢复能力**
   - 系统现在能够优雅地处理LLM调用失败
   - 提供了有意义的错误信息

### 🔧 修改的文件

1. `core/base_agent.py` - 添加None响应检查
2. `agents/enhanced_real_code_reviewer.py` - 统一LLM调用方式
3. `core/llm_communication/managers/client_manager.py` - 增强错误处理
4. `test_none_response_fix.py` - 创建测试脚本验证修复效果
5. `NONE_RESPONSE_FIX_REPORT.md` - 详细的修复报告文档

### 🎯 预期效果

- ✅ 不再出现 `object of type 'NoneType' has no len()` 错误
- ✅ 智能体能够正常处理LLM调用失败的情况
- ✅ 系统提供更好的错误恢复能力
- ✅ 统一的错误处理机制提高了系统稳定性

## 测试验证

运行测试脚本验证修复效果：

```bash
python test_none_response_fix.py
```

这些修复显著提高了系统的稳定性和可靠性，为后续的功能开发奠定了良好的基础。 