[2025-08-04 22:31:35] test_framework - ERROR - ❌ 测试失败: TaskContext.__init__() got an unexpected keyword argument 'conversation_id'. Did you mean 'conversation_history'?
[2025-08-04 22:31:35] test_framework - ERROR - 错误详情: Traceback (most recent call last):
  File "/Users/haiyan-mini/Documents/Study/V-Agent/test_llm_coordinator.py", line 66, in test_llm_coordinator_basic
    result = await coordinator.coordinate_task(
             ^^^^^^^^^^^^^^^^^^^^^^^^^^^^^^^^^^
    ...<3 lines>...
    )
    ^
  File "/Users/haiyan-mini/Documents/Study/V-Agent/core/llm_coordinator_agent.py", line 362, in coordinate_task
    task_context = TaskContext(
        task_id=task_id,
    ...<2 lines>...
        max_iterations=max_iterations
    )
TypeError: TaskContext.__init__() got an unexpected keyword argument 'conversation_id'. Did you mean 'conversation_history'?

[2025-08-04 22:31:35] test_framework - ERROR - ❌ 复杂任务测试失败: TaskContext.__init__() got an unexpected keyword argument 'conversation_id'. Did you mean 'conversation_history'?
[2025-08-04 22:31:35] test_framework - ERROR - ❌ 上下文保持测试失败: TaskContext.__init__() got an unexpected keyword argument 'conversation_id'. Did you mean 'conversation_history'?
[2025-08-04 22:31:35] test_framework - ERROR - ❌ 智能体选择测试失败: TaskContext.__init__() got an unexpected keyword argument 'conversation_id'. Did you mean 'conversation_history'?
